Workbook

Sheet 1-สรุปผู้บริหาร
B2: ECL Workbook v4 — ค่าเผื่อหนี้สงสัยจะสูญแบบแยกงวด (Per-Installment Aging)
B3: BESTCHOICE FINANCE | TFRS for NPAEs Ch.13 | สร้างจากตัวเลขระบบจริง (test goldens) 2026-07-27 | แทน workbook "Bug Fix #7"
B5: สิ่งที่เปลี่ยนจาก v3
B6: 1. วิธีคิดค่าเผื่อ: แยกงวด | C6: แต่ละงวดค้างใช้ rate ตาม bucket ของอายุตัวเอง แล้วรวมเป็นค่าเผื่อของสัญญา (เดิม: ทั้งสัญญา × rate งวดเก่าสุด) — ตาม sheet Scenarios ที่ CPA ระบุ "ที่ถูกต้อง!"
B7: 2. JP5/write-off: GL-based + Release | C7: ทุกบรรทัดล้างตามยอด GL จริง (ปิดบั๊ก over-credit เคสจ่ายบางส่วน) + release ค่าเผื่อส่วนเกินหลัง consume → 11-2102 = 0 เสมอ
B8: 3. TERMINATED: ACCRUED gate | C8: ตั้งค่าเผื่อเฉพาะงวดที่ accrue เข้า 11-2103 แล้ว — งวดหลังบอกเลิก (ดอกเบี้ยยังไม่รับรู้) ไม่ตั้งสำรอง
B9: 4. จ่ายบางส่วน: pro-rate + FEE-FIRST | C9: ฐาน ECL และ CN VAT ลดตามยอดค้างจริง โดยหักค่าปรับออกจากเงินรับก่อน (ค่าปรับไม่ใช่การชำระเงินต้น)
B10: 5. Streak floor: ปิด (dormant) | C10: กติกา "ค้างติดต่อกัน N งวด → floor bucket" ปิดไว้ตาม workbook นี้ (ไม่มีช่อง streak) — เปิดกลับได้ด้วย config 1 แถวถ้า CPA สั่ง
B11: 6. แก้เลขผิด v3 3 จุด | C11: Scenario D Net VAT 792.85→793.36 (count) / Cash Flow D →(2,245.87) / FIN-2024-010 → พร้อม JP5
B13: ผลกระทบต่อพอร์ต (10 สัญญา, ค้าง 42 งวด = 63,664.86 ฿)
B14: ค่าเผื่อวิธีเดิม v3 (ทั้งสัญญา × งวดเก่าสุด) | C14: ='2-พอร์ตสัญญา'!H17 -> 52356.78
B15: ค่าเผื่อวิธีใหม่ v4 (แยกงวด) | C15: ='2-พอร์ตสัญญา'!I17 -> 29907.32
B16: ลดลง (ระบบ release อัตโนมัติวันแรก — delta เทียบ GL) | C16: ='2-พอร์ตสัญญา'!H17-'2-พอร์ตสัญญา'!I17 -> 22449.46
B18: สถานะระบบ: implement + test ครบแล้วบน branch feat/ecl-per-installment (รอ CPA ยืนยัน 2 ข้อใน Sheet 8 ก่อน merge)

Sheet 2-พอร์ตสัญญา
B2: พอร์ตสัญญา 10 ตัว — ค่าเผื่อหนี้สงสัยจะสูญแบบแยกงวด (ECL v4)
B3: ยอดค้างต่องวด = 1,515.83 ฿ (fixture 17,000/12 + VAT) | อายุงวดชุด 15+30k วัน | ชื่อลูกค้าสมมุติเพื่ออธิบาย
B5: สัญญา | C5: ลูกค้า | D5: สถานะ | E5: งวดค้าง | F5: 11-2103 (฿) | G5: Bucket เก่าสุด | H5: ค่าเผื่อวิธีเดิม v3 (฿) | I5: ค่าเผื่อแยกงวด v4 (฿) | J5: ผลต่าง (release) (฿)
B6: FIN-2024-003 | C6: สมศักดิ์ | D6: ACTIVE | E6: 1 | F6: =E6*$G$18 -> 1515.83 | G6: =E22 -> B1 1-30 | H6: =ROUND(F6*VLOOKUP(G6,'3-Aging-Bucket'!$B$5:$D$10,3,0),2) -> 30.32 | I6: =SUM(H22:H22) -> 30.32 | J6: =H6-I6 -> 0
B7: FIN-2024-012 | C7: วิภาดา | D7: ACTIVE | E7: 1 | F7: =E7*$G$18 -> 1515.83 | G7: =E23 -> B1 1-30 | H7: =ROUND(F7*VLOOKUP(G7,'3-Aging-Bucket'!$B$5:$D$10,3,0),2) -> 30.32 | I7: =SUM(H23:H23) -> 30.32 | J7: =H7-I7 -> 0
B8: FIN-2024-004 | C8: ประเสริฐ | D8: OVERDUE | E8: 3 | F8: =E8*$G$18 -> 4547.49 | G8: =E24 -> B3 61-90 | H8: =ROUND(F8*VLOOKUP(G8,'3-Aging-Bucket'!$B$5:$D$10,3,0),2) -> 2273.75 | I8: =SUM(H24:H26) -> 1015.61 | J8: =H8-I8 -> 1258.14
B9: FIN-2024-010 | C9: จันทร์เพ็ญ | D9: TERMINATED | E9: 5 | F9: =E9*$G$18 -> 7579.15 | G9: =E27 -> B4 91-180 | H9: =ROUND(F9*VLOOKUP(G9,'3-Aging-Bucket'!$B$5:$D$10,3,0),2) -> 5684.36 | I9: =SUM(H27:H31) -> 3289.35 | J9: =H9-I9 -> 2395.01
B10: FIN-2024-067 | C10: อนุชา | D10: TERMINATED | E10: 5 | F10: =E10*$G$18 -> 7579.15 | G10: =E32 -> B4 91-180 | H10: =ROUND(F10*VLOOKUP(G10,'3-Aging-Bucket'!$B$5:$D$10,3,0),2) -> 5684.36 | I10: =SUM(H32:H36) -> 3289.35 | J10: =H10-I10 -> 2395.01
B11: FIN-2024-089 | C11: รัตนา | D11: TERMINATED | E11: 6 | F11: =E11*$G$18 -> 9094.98 | G11: =E37 -> B4 91-180 | H11: =ROUND(F11*VLOOKUP(G11,'3-Aging-Bucket'!$B$5:$D$10,3,0),2) -> 6821.24 | I11: =SUM(H37:H42) -> 4426.22 | J11: =H11-I11 -> 2395.02
B12: FIN-2024-005 | C12: สมหมาย | D12: TERMINATED | E12: 7 | F12: =E12*$G$18 -> 10610.81 | G12: =E43 -> B5 180+ | H12: =ROUND(F12*VLOOKUP(G12,'3-Aging-Bucket'!$B$5:$D$10,3,0),2) -> 10610.81 | I12: =SUM(H43:H49) -> 5942.05 | J12: =H12-I12 -> 4668.76
B13: FIN-2024-045 | C13: กิตติพงษ์ | D13: TERMINATED | E13: 7 | F13: =E13*$G$18 -> 10610.81 | G13: =E50 -> B5 180+ | H13: =ROUND(F13*VLOOKUP(G13,'3-Aging-Bucket'!$B$5:$D$10,3,0),2) -> 10610.81 | I13: =SUM(H50:H56) -> 5942.05 | J13: =H13-I13 -> 4668.76
B14: FIN-2024-023 | C14: ดวงใจ | D14: TERMINATED | E14: 7 | F14: =E14*$G$18 -> 10610.81 | G14: =E57 -> B5 180+ | H14: =ROUND(F14*VLOOKUP(G14,'3-Aging-Bucket'!$B$5:$D$10,3,0),2) -> 10610.81 | I14: =SUM(H57:H63) -> 5942.05 | J14: =H14-I14 -> 4668.76
B15: FIN-2024-101 | C15: ศิริพร | D15: ACTIVE (B0) | E15: 0 | F15: =E15*$G$18 -> 0 | G15: B0 ปกติ | H15: 0 | I15: 0 | J15: =H15-I15 -> 0
B17: รวมพอร์ต | E17: =SUM(E6:E15) -> 42 | F17: =SUM(F6:F15) -> 63664.86 | H17: =SUM(H6:H15) -> 52356.78 | I17: =SUM(I6:I15) -> 29907.32 | J17: =SUM(J6:J15) -> 22449.46
B18: ยอดต่องวด (฿) | G18: 1515.83 | H18: ← Source: 17,000/12 ROUND_DOWN + 1,190/12 HALF_UP (accounting.md rounding modes)
B20: รายละเอียดรายงวดค้าง (42 งวด) — แต่ละงวดใช้ rate ตาม bucket ของอายุตัวเอง
B21: สัญญา | C21: งวดที่ | D21: อายุค้าง (วัน) | E21: Bucket | F21: Rate | G21: ยอดค้าง (฿) | H21: ค่าเผื่อ (฿)
B22: FIN-2024-003 | C22: 4 | D22: 15 | E22: =IF(D22=0,"B0 ปกติ",IF(D22<=30,"B1 1-30",IF(D22<=60,"B2 31-60",IF(D22<=90,"B3 61-90",IF(D22<=180,"B4 91-180","B5 180+"))))) -> B1 1-30 | F22: =VLOOKUP(E22,'3-Aging-Bucket'!$B$5:$D$10,3,0) -> 0.02 | G22: =$G$18 -> 1515.83 | H22: =ROUND(G22*F22,2) -> 30.32
B23: FIN-2024-012 | C23: 6 | D23: 15 | E23: =IF(D23=0,"B0 ปกติ",IF(D23<=30,"B1 1-30",IF(D23<=60,"B2 31-60",IF(D23<=90,"B3 61-90",IF(D23<=180,"B4 91-180","B5 180+"))))) -> B1 1-30 | F23: =VLOOKUP(E23,'3-Aging-Bucket'!$B$5:$D$10,3,0) -> 0.02 | G23: =$G$18 -> 1515.83 | H23: =ROUND(G23*F23,2) -> 30.32
B24: FIN-2024-004 | C24: 6 | D24: 75 | E24: =IF(D24=0,"B0 ปกติ",IF(D24<=30,"B1 1-30",IF(D24<=60,"B2 31-60",IF(D24<=90,"B3 61-90",IF(D24<=180,"B4 91-180","B5 180+"))))) -> B3 61-90 | F24: =VLOOKUP(E24,'3-Aging-Bucket'!$B$5:$D$10,3,0) -> 0.5 | G24: =$G$18 -> 1515.83 | H24: =ROUND(G24*F24,2) -> 757.92
B25: FIN-2024-004 | C25: 7 | D25: 45 | E25: =IF(D25=0,"B0 ปกติ",IF(D25<=30,"B1 1-30",IF(D25<=60,"B2 31-60",IF(D25<=90,"B3 61-90",IF(D25<=180,"B4 91-180","B5 180+"))))) -> B2 31-60 | F25: =VLOOKUP(E25,'3-Aging-Bucket'!$B$5:$D$10,3,0) -> 0.15 | G25: =$G$18 -> 1515.83 | H25: =ROUND(G25*F25,2) -> 227.37
B26: FIN-2024-004 | C26: 8 | D26: 15 | E26: =IF(D26=0,"B0 ปกติ",IF(D26<=30,"B1 1-30",IF(D26<=60,"B2 31-60",IF(D26<=90,"B3 61-90",IF(D26<=180,"B4 91-180","B5 180+"))))) -> B1 1-30 | F26: =VLOOKUP(E26,'3-Aging-Bucket'!$B$5:$D$10,3,0) -> 0.02 | G26: =$G$18 -> 1515.83 | H26: =ROUND(G26*F26,2) -> 30.32
B27: FIN-2024-010 | C27: 6 | D27: 135 | E27: =IF(D27=0,"B0 ปกติ",IF(D27<=30,"B1 1-30",IF(D27<=60,"B2 31-60",IF(D27<=90,"B3 61-90",IF(D27<=180,"B4 91-180","B5 180+"))))) -> B4 91-180 | F27: =VLOOKUP(E27,'3-Aging-Bucket'!$B$5:$D$10,3,0) -> 0.75 | G27: =$G$18 -> 1515.83 | H27: =ROUND(G27*F27,2) -> 1136.87
B28: FIN-2024-010 | C28: 7 | D28: 105 | E28: =IF(D28=0,"B0 ปกติ",IF(D28<=30,"B1 1-30",IF(D28<=60,"B2 31-60",IF(D28<=90,"B3 61-90",IF(D28<=180,"B4 91-180","B5 180+"))))) -> B4 91-180 | F28: =VLOOKUP(E28,'3-Aging-Bucket'!$B$5:$D$10,3,0) -> 0.75 | G28: =$G$18 -> 1515.83 | H28: =ROUND(G28*F28,2) -> 1136.87
B29: FIN-2024-010 | C29: 8 | D29: 75 | E29: =IF(D29=0,"B0 ปกติ",IF(D29<=30,"B1 1-30",IF(D29<=60,"B2 31-60",IF(D29<=90,"B3 61-90",IF(D29<=180,"B4 91-180","B5 180+"))))) -> B3 61-90 | F29: =VLOOKUP(E29,'3-Aging-Bucket'!$B$5:$D$10,3,0) -> 0.5 | G29: =$G$18 -> 1515.83 | H29: =ROUND(G29*F29,2) -> 757.92
B30: FIN-2024-010 | C30: 9 | D30: 45 | E30: =IF(D30=0,"B0 ปกติ",IF(D30<=30,"B1 1-30",IF(D30<=60,"B2 31-60",IF(D30<=90,"B3 61-90",IF(D30<=180,"B4 91-180","B5 180+"))))) -> B2 31-60 | F30: =VLOOKUP(E30,'3-Aging-Bucket'!$B$5:$D$10,3,0) -> 0.15 | G30: =$G$18 -> 1515.83 | H30: =ROUND(G30*F30,2) -> 227.37
B31: FIN-2024-010 | C31: 10 | D31: 15 | E31: =IF(D31=0,"B0 ปกติ",IF(D31<=30,"B1 1-30",IF(D31<=60,"B2 31-60",IF(D31<=90,"B3 61-90",IF(D31<=180,"B4 91-180","B5 180+"))))) -> B1 1-30 | F31: =VLOOKUP(E31,'3-Aging-Bucket'!$B$5:$D$10,3,0) -> 0.02 | G31: =$G$18 -> 1515.83 | H31: =ROUND(G31*F31,2) -> 30.32
B32: FIN-2024-067 | C32: 6 | D32: 135 | E32: =IF(D32=0,"B0 ปกติ",IF(D32<=30,"B1 1-30",IF(D32<=60,"B2 31-60",IF(D32<=90,"B3 61-90",IF(D32<=180,"B4 91-180","B5 180+"))))) -> B4 91-180 | F32: =VLOOKUP(E32,'3-Aging-Bucket'!$B$5:$D$10,3,0) -> 0.75 | G32: =$G$18 -> 1515.83 | H32: =ROUND(G32*F32,2) -> 1136.87
B33: FIN-2024-067 | C33: 7 | D33: 105 | E33: =IF(D33=0,"B0 ปกติ",IF(D33<=30,"B1 1-30",IF(D33<=60,"B2 31-60",IF(D33<=90,"B3 61-90",IF(D33<=180,"B4 91-180","B5 180+"))))) -> B4 91-180 | F33: =VLOOKUP(E33,'3-Aging-Bucket'!$B$5:$D$10,3,0) -> 0.75 | G33: =$G$18 -> 1515.83 | H33: =ROUND(G33*F33,2) -> 1136.87
... B63: FIN-2024-023 | C63: 12 | D63: 15 | E63: =IF(D63=0,"B0 ปกติ",IF(D63<=30,"B1 1-30",IF(D63<=60,"B2 31-60",IF(D63<=90,"B3 61-90",IF(D63<=180,"B4 91-180","B5 180+"))))) -> B1 1-30 | F63: =VLOOKUP(E63,'3-Aging-Bucket'!$B$5:$D$10,3,0) -> 0.02 | G63: =$G$18 -> 1515.83 | H63: =ROUND(G63*F63,2) -> 30.32
B65: รวม 42 งวด | G65: =SUM(G22:G63) -> 63664.86 | H65: =SUM(H22:H63) -> 29907.32
B67: หมายเหตุ TERMINATED (ACCRUED gate): ตั้งค่าเผื่อเฉพาะงวดที่ accrue เข้า 11-2103 แล้วเท่านั้น — งวดหลังบอกเลิก (2A หยุด) ไม่ตั้งสำรอง
B68: ตัวอย่างจากระบบ: TERMINATED มี 3 งวด accrued (100/70/40 วัน) + 2 งวดเลยกำหนดแต่ไม่เคย accrue → ค่าเผื่อ = 2,122.16 (ไม่ใช่ 2,183.12) — ecl-terminated-base.spec.ts

Sheet 3-Aging-Bucket
B2: Aging Buckets — อัตราตั้งค่าเผื่อ (ECL v4 แยกงวด) | F2: สรุปรายงวดค้างทั้งพอร์ต (aggregate จาก Sheet 2)
B3: Source: SystemConfig bad_debt_provision_rates + bad-debt.service.ts (TFRS for NPAEs Ch.13)
B4: Bucket | C4: วันค้าง | D4: Rate | F4: Bucket | G4: จำนวนงวด | H4: ฐานยอดค้าง (฿) | I4: ค่าเผื่อ (฿) | J4: % ของฐาน
B5: B0 ปกติ | C5: 0 | D5: 0 | F5: B1 1-30 | G5: =COUNTIF('2-พอร์ตสัญญา'!$E$22:$E$63,F5) -> 9 | H5: =SUMIF('2-พอร์ตสัญญา'!$E$22:$E$63,F5,'2-พอร์ตสัญญา'!$G$22:$G$63) -> 13642.47 | I5: =SUMIF('2-พอร์ตสัญญา'!$E$22:$E$63,F5,'2-พอร์ตสัญญา'!$H$22:$H$63) -> 272.88 | J5: =IF($H$10=0,0,H5/$H$10) -> 0.21428571
B6: B1 1-30 | C6: 1-30 | D6: 0.02 | F6: B2 31-60 | G6: =COUNTIF('2-พอร์ตสัญญา'!$E$22:$E$63,F6) -> 7 | H6: =SUMIF('2-พอร์ตสัญญา'!$E$22:$E$63,F6,'2-พอร์ตสัญญา'!$G$22:$G$63) -> 10610.81 | I6: =SUMIF('2-พอร์ตสัญญา'!$E$22:$E$63,F6,'2-พอร์ตสัญญา'!$H$22:$H$63) -> 1591.59 | J6: =IF($H$10=0,0,H6/$H$10) -> 0.16666667
B7: B2 31-60 | C7: 31-60 | D7: 0.15 | F7: B3 61-90 | G7: =COUNTIF('2-พอร์ตสัญญา'!$E$22:$E$63,F7) -> 7 | H7: =SUMIF('2-พอร์ตสัญญา'!$E$22:$E$63,F7,'2-พอร์ตสัญญา'!$G$22:$G$63) -> 10610.81 | I7: =SUMIF('2-พอร์ตสัญญา'!$E$22:$E$63,F7,'2-พอร์ตสัญญา'!$H$22:$H$63) -> 5305.44 | J7: =IF($H$10=0,0,H7/$H$10) -> 0.16666667
B8: B3 61-90 | C8: 61-90 | D8: 0.5 | F8: B4 91-180 | G8: =COUNTIF('2-พอร์ตสัญญา'!$E$22:$E$63,F8) -> 16 | H8: =SUMIF('2-พอร์ตสัญญา'!$E$22:$E$63,F8,'2-พอร์ตสัญญา'!$G$22:$G$63) -> 24253.28 | I8: =SUMIF('2-พอร์ตสัญญา'!$E$22:$E$63,F8,'2-พอร์ตสัญญา'!$H$22:$H$63) -> 18189.92 | J8: =IF($H$10=0,0,H8/$H$10) -> 0.38095238
B9: B4 91-180 | C9: 91-180 | D9: 0.75 | F9: B5 180+ | G9: =COUNTIF('2-พอร์ตสัญญา'!$E$22:$E$63,F9) -> 3 | H9: =SUMIF('2-พอร์ตสัญญา'!$E$22:$E$63,F9,'2-พอร์ตสัญญา'!$G$22:$G$63) -> 4547.49 | I9: =SUMIF('2-พอร์ตสัญญา'!$E$22:$E$63,F9,'2-พอร์ตสัญญา'!$H$22:$H$63) -> 4547.49 | J9: =IF($H$10=0,0,H9/$H$10) -> 0.071428571
B10: B5 180+ | C10: >180 | D10: 1 | F10: รวม | G10: =SUM(G5:G9) -> 42 | H10: =SUM(H5:H9) -> 63664.86 | I10: =SUM(I5:I9) -> 29907.32 | J10: =IF(H10=0,0,H10/H10) -> 1
F12: เช็ค: ฐานรวมต้องเท่า 11-2103 รวมพอร์ต 63,664.86 = | I12: =IF(ROUND(H10,2)=ROUND('2-พอร์ตสัญญา'!F17,2),"✔ ตรง","✘ ไม่ตรง") -> ✔ ตรง
F14: หมายเหตุ: จำนวนงวด = นับเป็น "งวด" ไม่ใช่สัญญา (สัญญาเดียวกระจายได้หลาย bucket — วิธีแยกงวด)

Sheet 4-Scenarios-สมศักดิ์
B2: Scenario A-D — สมศักดิ์ FIN-2024-003 บอกเลิก+ยึด ณ งวดต่างกัน (จำลอง)
B3: จ่ายงวด 1-3 แล้วหยุด | 2A accrue ถึงงวดที่บอกเลิก | ยึดได้ราคากลาง 5,000 ฿ | ตัวเลข GL-based (ระบบ canonical — ต่างจาก count-based เดิม ±สตางค์)
C5: A | D5: B | E5: C | F5: D
B6: บอกเลิกที่งวด (k = งวดที่ accrue แล้ว) | C6: 4 | D6: 5 | E6: 6 | F6: 7 | G6: Scenario A ยึดที่ 45 วัน = ต่ำกว่าเกณฑ์ policy 60 วัน (แสดงไว้เพื่อเปรียบเทียบ)
B7: อายุงวดค้างเก่าสุด ณ วันยึด (วัน) | C7: 45 | D7: 75 | E7: 105 | F7: 135 | G7: อายุแถวนี้ = ณ วันยึด; ค่าเผื่อแถว 16 = snapshot cron สิ้นเดือนก่อนยึด (อายุน้อยกว่า ~30 วัน: 30/60/90/120) — สองแถวไม่ขัดกัน
B8: งวดค้าง (k−3) | C8: =C6-3 -> 1 | D8: =D6-3 -> 2 | E8: =E6-3 -> 3 | F8: =F6-3 -> 4
B9: 11-2103 ลูกหนี้ค้าง = (k−3)×1,515.83 | C9: =C8*'2-พอร์ตสัญญา'!$G$18 -> 1515.83 | D9: =D8*'2-พอร์ตสัญญา'!$G$18 -> 3031.66 | E9: =E8*'2-พอร์ตสัญญา'!$G$18 -> 4547.49 | F9: =F8*'2-พอร์ตสัญญา'!$G$18 -> 6063.32 | G9: GL หลัง 2A×k + 2B×3 — สมการเดียวกับ jp5-vat-split.spec.ts
B10: 11-2101 Gross คงเหลือ = 17,000 − k×1,416.66 | C10: =17000-C6*1416.66 -> 11333.36 | D10: =17000-D6*1416.66 -> 9916.7 | E10: =17000-E6*1416.66 -> 8500.04 | F10: =17000-F6*1416.66 -> 7083.38
B11: 11-2106 ดอกเบี้ยรอตัด = 6,000 − k×500 | C11: =6000-C6*500 -> 4000 | D11: =6000-D6*500 -> 3500 | E11: =6000-E6*500 -> 3000 | F11: =6000-F6*500 -> 2500
B12: 11-2105 = 21-2102 = 1,190 − k×99.17 | C12: =1190-C6*99.17 -> 793.32 | D12: =1190-D6*99.17 -> 694.15 | E12: =1190-E6*99.17 -> 594.98 | F12: =1190-F6*99.17 -> 495.81
B13: CN VAT ม.82/5 (Dr 21-2101) = (k−3)×99.17 | C13: =C8*99.17 -> 99.17 | D13: =D8*99.17 -> 198.34 | E13: =E8*99.17 -> 297.51 | F13: =F8*99.17 -> 396.68
B14: เงินสดรับจากยึด | C14: 5000 | D14: 5000 | E14: 5000 | F14: 5000
B15: Gross Loss = 2103+2101+2105 − เงินสด − CN VAT | C15: =C9+C10+C12-C14-C13 -> 8543.34 | D15: =D9+D10+D12-D14-D13 -> 8444.17 | E15: =E9+E10+E12-E14-E13 -> 8345 | F15: =F9+F10+F12-F14-F13 -> 8245.83 | G15: A = 8,543.34 → plug 8,513.02 (ปักใน jp5-vat-split.spec.ts)
B16: ค่าเผื่อสะสม (แยกงวด) ณ สิ้นเดือนก่อนยึด | C16: 30.32 | D16: 257.69 | E16: 1015.61 | F16: 2152.48 | G16: ชุดค่าเผื่อ ณ อายุ {30}/{60,30}/{90,60,30}/{120,90,60,30} วัน — goldens bad-debt.service.spec.ts
B17: Consume ค่าเผื่อ (Dr 11-2102) = min(Loss, ค่าเผื่อ) | C17: =MIN(C15,C16) -> 30.32 | D17: =MIN(D15,D16) -> 257.69 | E17: =MIN(E15,E16) -> 1015.61 | F17: =MIN(F15,F16) -> 2152.48
B18: Release ค่าเผื่อคงเหลือ (Dr 11-2102/Cr 51-1103) | C18: =C16-C17 -> 0 | D18: =D16-D17 -> 0 | E18: =E16-E17 -> 0 | F18: =F16-F17 -> 0
B19: Net Loss 51-1102 (plug) = Loss − Consume | C19: =C15-C17 -> 8513.02 | D19: =D15-D17 -> 8186.48 | E19: =E15-E17 -> 7329.39 | F19: =F15-F17 -> 6093.35
B20: 11-2102 หลัง JP5 (ต้องเป็น 0) | C20: =C16-C17-C18 -> 0 | D20: =D16-D17-D18 -> 0 | E20: =E16-E17-E18 -> 0 | F20: =F16-F17-F18 -> 0
B21: Net VAT นำส่งสะสมทั้งสัญญา = 1,190 − CN VAT | C21: =1190-C13 -> 1090.83 | D21: =1190-D13 -> 991.66 | E21: =1190-E13 -> 892.49 | F21: =1190-F13 -> 793.32 | G21: label เดิม "(Period)" → "สะสม" (แก้ตาม audit) | v3 count-based: D = 793.36, GL-based = 793.32 (เศษ 12×99.17=1,190.04)
B22: Net Cash Flow = 4,547.49 + 5,000 − 11,000 − NetVAT | C22: =4547.49+C14-11000-C21 -> -2543.34 | D22: =4547.49+D14-11000-D21 -> -2444.17 | E22: =4547.49+E14-11000-E21 -> -2345 | F22: =4547.49+F14-11000-F21 -> -2245.83 | G22: v3 (แก้เลขผิดแล้ว) D = −2,245.87 count-based → GL-based = −2,245.83
B25: เคสจ่ายบางส่วน — pro-rate (กติกา CPA 2026-07-26)
B26: กรณี (งวดเดียว ค้าง 1,515.83) | C26: เงินรับ | D26: ค่าปรับ (FEE-FIRST) | E26: ยอดค้างสุทธิ | F26: ECL 31-60 (15%) | G26: CN VAT pro-rate | H26: CN ก่อน VAT
B27: จ่าย 1,000 ไม่มีค่าปรับ | C27: 1000 | D27: 0 | E27: ='2-พอร์ตสัญญา'!$G$18-(C27-D27) -> 515.83 | F27: =ROUND(E27*0.15,2) -> 77.37 | G27: =ROUND(99.17*E27/'2-พอร์ตสัญญา'!$G$18,2) -> 33.75 | H27: =E27-G27 -> 482.08
B28: จ่าย 1,000 มีค่าปรับ 75.79 (หักค่าปรับก่อน) | C28: 1000 | D28: 75.79 | E28: ='2-พอร์ตสัญญา'!$G$18-(C28-D28) -> 591.62 | F28: =ROUND(E28*0.15,2) -> 88.74 | G28: =ROUND(99.17*E28/'2-พอร์ตสัญญา'!$G$18,2) -> 38.71 | H28: =E28-G28 -> 552.91
B30: Goldens ระบบ: ค้าง 515.83 → CN VAT 33.75 / ก่อน VAT 482.08 / ECL 77.37 | มีค่าปรับ: ค้าง 591.62 → CN VAT 38.71 (compute-cn-breakdown.spec.ts) | ใบลดหนี้จริงแสดง amountBeforeVat ตามนี้

Sheet 5-JE-สมศักดิ์
B2: JE ครบชุด — สมศักดิ์ FIN-2024-003 (Scenario A จำลอง — ไม่ใช่รายการจริงใน GL)
B3: Source: case-1-overpay.csv (1A/2A/2B/จุด3) + jp5-vat-split.spec.ts Scenario A (JP5 GL-based)
B5: 1A — วันทำสัญญา (Dr=Cr 18,190.00)
B6: บัญชี | C6: ชื่อบัญชี | D6: Dr (฿) | E6: Cr (฿)
B7: 11-2101 | C7: ลูกหนี้ผ่อนชำระ Gross (ไม่รวม VAT) | D7: 17000
B8: 11-2105 | C8: ลูกหนี้ภาษีขายรอเรียกเก็บ | D8: 1190
B9: 21-1101 | C9: เจ้าหนี้-หน้าร้าน (ยอดจัด) | E9: 10000
B10: 21-1102 | C10: เจ้าหนี้ค่าคอม-หน้าร้าน | E10: 1000
B11: 11-2106 | C11: รายได้รอตัดบัญชี-ดอกเบี้ย (หัก) | E11: 6000
B12: 21-2102 | C12: ภาษีขายรอเรียกเก็บ | E12: 1190
C13: รวม (ต้อง Dr = Cr) | D13: =SUM(D7:D12) -> 18190 | E13: =SUM(E7:E12) -> 18190 | F13: =IF(ROUND(D13,2)=ROUND(E13,2),"✔ BALANCED","✘ UNBALANCED") -> ✔ BALANCED
B15: จุดที่ 3 — จ่ายหน้าร้าน 11,000.00
B16: บัญชี | C16: ชื่อบัญชี | D16: Dr (฿) | E16: Cr (฿)
B17: 21-1101 | C17: เจ้าหนี้-หน้าร้าน | D17: 10000
B18: 21-1102 | C18: เจ้าหนี้ค่าคอม-หน้าร้าน | D18: 1000
B19: 11-1201 | C19: ธนาคาร KBank | E19: 11000
C20: รวม (ต้อง Dr = Cr) | D20: =SUM(D17:D19) -> 11000 | E20: =SUM(E17:E19) -> 11000 | F20: =IF(ROUND(D20,2)=ROUND(E20,2),"✔ BALANCED","✘ UNBALANCED") -> ✔ BALANCED
B22: 2A — ถึงกำหนดงวด (ต่องวด, ระบบ post อัตโนมัติ 00:01 — เกิด 4 ครั้ง งวด 1-4) | F22: รวมต่อครั้ง 2,115.00 × 4 ครั้ง
B23: บัญชี | C23: ชื่อบัญชี | D23: Dr (฿) | E23: Cr (฿)
B24: 11-2103 | C24: ลูกหนี้ค้างชำระ (Accrual) | D24: 1515.83
B25: 21-2102 | C25: ล้างภาษีขายรอเรียกเก็บ | D25: 99.17
B26: 11-2106 | C26: รายได้รอตัดบัญชี-ดอกเบี้ย (ตัดงวดนี้) | D26: 500
B27: 11-2101 | C27: ลูกหนี้ Gross (ลด) | E27: 1416.66
B28: 11-2105 | C28: ลูกหนี้ภาษีขายรอฯ (ล้าง) | E28: 99.17
B29: 21-2101 | C29: ภาษีขาย ภ.พ.30 | E29: 99.17
B30: 41-1101 | C30: รายได้ดอกเบี้ย | E30: 500
C31: รวม (ต้อง Dr = Cr) | D31: =SUM(D24:D30) -> 2115 | E31: =SUM(E24:E30) -> 2115 | F31: =IF(ROUND(D31,2)=ROUND(E31,2),"✔ BALANCED","✘ UNBALANCED") -> ✔ BALANCED
B33: 2B — รับชำระงวด (เกิด 3 ครั้ง งวด 1-3) | F33: × 3 ครั้ง = 4,547.49
B34: บัญชี | C34: ชื่อบัญชี | D34: Dr (฿) | E34: Cr (฿)
B35: 11-1101 | C35: เงินสด | D35: 1515.83
B36: 11-2103 | C36: ลูกหนี้ค้างชำระ (ล้าง) | E36: 1515.83
C37: รวม (ต้อง Dr = Cr) | D37: =SUM(D35:D36) -> 1515.83 | E37: =SUM(E35:E36) -> 1515.83 | F37: =IF(ROUND(D37,2)=ROUND(E37,2),"✔ BALANCED","✘ UNBALANCED") -> ✔ BALANCED
B39: PROV — ตั้งค่าเผื่อ (cron 00:30 — งวด 4 ค้าง 1-30 วัน @2%)
B40: บัญชี | C40: ชื่อบัญชี | D40: Dr (฿) | E40: Cr (฿)
B41: 51-1103 | C41: ค่าเผื่อหนี้สงสัยจะสูญ (เพิ่มในปี) | D41: 30.32
B42: 11-2102 | C42: ค่าเผื่อหนี้สงสัยจะสูญ (Contra) | E42: 30.32
C43: รวม (ต้อง Dr = Cr) | D43: =SUM(D41:D42) -> 30.32 | E43: =SUM(E41:E42) -> 30.32 | F43: =IF(ROUND(D43,2)=ROUND(E43,2),"✔ BALANCED","✘ UNBALANCED") -> ✔ BALANCED
B45: JP5 — ยึดสินค้า (GL-based ทุกบรรทัด — Dr=Cr 18,435.83) | F45: Release residual = 0.00 (ค่าเผื่อ 30.32 < Loss → consume หมด) | metadata.releasedProvision = "0.00"
B46: บัญชี | C46: ชื่อบัญชี | D46: Dr (฿) | E46: Cr (฿)
B47: 11-1101 | C47: เงินสด (ราคากลางยึด) | D47: 5000
...

Sheet 6-JP5-Breakdown
B2: JP5 Breakdown — 6 สัญญาพร้อมยึด (GL-based + Release Residual)
B3: สมมุติยึดได้ราคากลาง 5,000 ฿/เครื่อง | ค่าเผื่อ ณ วันยึด = ค่าเผื่อแยกงวด v4 | Loss = 2103+2101+2105 − เงินสด − CN VAT
B5: สัญญา | C5: สถานะ | D5: จ่ายแล้ว j | E5: Accrued k | F5: ค้าง | G5: 11-2103 | H5: 11-2101 คงเหลือ | I5: 11-2106 | J5: 11-2105 | K5: CN VAT | L5: เงินสดยึด | M5: Gross Loss | N5: ค่าเผื่อ v4 | O5: Consume | P5: Release | Q5: Net Loss 51-1102 | R5: 11-2102 หลัง
B6: FIN-2024-010 | C6: TERMINATED | D6: 5 | E6: 10 | F6: =E6-D6 -> 5 | G6: =F6*'2-พอร์ตสัญญา'!$G$18 -> 7579.15 | H6: =17000-E6*1416.66 -> 2833.4 | I6: =6000-E6*500 -> 1000 | J6: =1190-E6*99.17 -> 198.3 | K6: =F6*99.17 -> 495.85 | L6: 5000 | M6: =G6+H6+J6-L6-K6 -> 5115 | N6: ='2-พอร์ตสัญญา'!I9 -> 3289.35 | O6: =MIN(M6,N6) -> 3289.35 | P6: =N6-O6 -> 0 | Q6: =M6-O6 -> 1825.65 | R6: =N6-O6-P6 -> 0
B7: FIN-2024-067 | C7: TERMINATED | D7: 5 | E7: 10 | F7: =E7-D7 -> 5 | G7: =F7*'2-พอร์ตสัญญา'!$G$18 -> 7579.15 | H7: =17000-E7*1416.66 -> 2833.4 | I7: =6000-E7*500 -> 1000 | J7: =1190-E7*99.17 -> 198.3 | K7: =F7*99.17 -> 495.85 | L7: 5000 | M7: =G7+H7+J7-L7-K7 -> 5115 | N7: ='2-พอร์ตสัญญา'!I10 -> 3289.35 | O7: =MIN(M7,N7) -> 3289.35 | P7: =N7-O7 -> 0 | Q7: =M7-O7 -> 1825.65 | R7: =N7-O7-P7 -> 0
B8: FIN-2024-089 | C8: TERMINATED | D8: 5 | E8: 11 | F8: =E8-D8 -> 6 | G8: =F8*'2-พอร์ตสัญญา'!$G$18 -> 9094.98 | H8: =17000-E8*1416.66 -> 1416.74 | I8: =6000-E8*500 -> 500 | J8: =1190-E8*99.17 -> 99.13 | K8: =F8*99.17 -> 595.02 | L8: 5000 | M8: =G8+H8+J8-L8-K8 -> 5015.83 | N8: ='2-พอร์ตสัญญา'!I11 -> 4426.22 | O8: =MIN(M8,N8) -> 4426.22 | P8: =N8-O8 -> 0 | Q8: =M8-O8 -> 589.61 | R8: =N8-O8-P8 -> 0
B9: FIN-2024-005 | C9: TERMINATED | D9: 5 | E9: 12 | F9: =E9-D9 -> 7 | G9: =F9*'2-พอร์ตสัญญา'!$G$18 -> 10610.81 | H9: =17000-E9*1416.66 -> 0.08 | I9: =6000-E9*500 -> 0 | J9: =1190-E9*99.17 -> -0.04 | K9: =F9*99.17 -> 694.19 | L9: 5000 | M9: =G9+H9+J9-L9-K9 -> 4916.66 | N9: ='2-พอร์ตสัญญา'!I12 -> 5942.05 | O9: =MIN(M9,N9) -> 4916.66 | P9: =N9-O9 -> 1025.39 | Q9: =M9-O9 -> 0 | R9: =N9-O9-P9 -> 0
B10: FIN-2024-045 | C10: TERMINATED | D10: 5 | E10: 12 | F10: =E10-D10 -> 7 | G10: =F10*'2-พอร์ตสัญญา'!$G$18 -> 10610.81 | H10: =17000-E10*1416.66 -> 0.08 | I10: =6000-E10*500 -> 0 | J10: =1190-E10*99.17 -> -0.04 | K10: =F10*99.17 -> 694.19 | L10: 5000 | M10: =G10+H10+J10-L10-K10 -> 4916.66 | N10: ='2-พอร์ตสัญญา'!I13 -> 5942.05 | O10: =MIN(M10,N10) -> 4916.66 | P10: =N10-O10 -> 1025.39 | Q10: =M10-O10 -> 0 | R10: =N10-O10-P10 -> 0
B11: FIN-2024-023 | C11: TERMINATED | D11: 5 | E11: 12 | F11: =E11-D11 -> 7 | G11: =F11*'2-พอร์ตสัญญา'!$G$18 -> 10610.81 | H11: =17000-E11*1416.66 -> 0.08 | I11: =6000-E11*500 -> 0 | J11: =1190-E11*99.17 -> -0.04 | K11: =F11*99.17 -> 694.19 | L11: 5000 | M11: =G11+H11+J11-L11-K11 -> 4916.66 | N11: ='2-พอร์ตสัญญา'!I14 -> 5942.05 | O11: =MIN(M11,N11) -> 4916.66 | P11: =N11-O11 -> 1025.39 | Q11: =M11-O11 -> 0 | R11: =N11-O11-P11 -> 0
B12: รวม | G12: =SUM(G6:G11) -> 56085.71 | H12: =SUM(H6:H11) -> 7083.78 | I12: =SUM(I6:I11) -> 2500 | J12: =SUM(J6:J11) -> 495.61 | K12: =SUM(K6:K11) -> 3669.29 | L12: =SUM(L6:L11) -> 30000 | M12: =SUM(M6:M11) -> 29995.81 | N12: =SUM(N6:N11) -> 28831.07 | ... R12: =SUM(R6:R11) -> 0
B14: คอลัมน์ Release (ใหม่ v4): สัญญา B5 accrue ครบ 12 งวด — ค่าเผื่อ 5,942.05 > Loss 4,916.66 → consume 4,916.66 + release 1,025.39 → 11-2102 = 0 (เดิม v3 ค่าเผื่อส่วนเกินค้างเงียบ)
B15: สัญญา k=12: 11-2101 เหลือ 0.08 และ 11-2105 เหลือ −0.04 (เศษปัด 12 งวด) — JP5 GL-based กวาดปิดอัตโนมัติเข้า Loss (นโยบายสตางค์: ระบบ canonical)
B16: v3 เดิมนับ 5 สัญญา (CN 3,173.44) — v4 นับ 6 สัญญาตาม summary "พร้อม JP5 = 6" ที่แก้แล้ว (รวม FIN-2024-010)

Sheet 7-ติดตามบอกเลิก
B2: ติดตามบอกเลิกสัญญา + สถานะ JP5
B3: เกณฑ์: ค้างเก่าสุด ≥ 90 วัน + TERMINATED = พร้อม JP5 (jp5_require_terminated_status = true — ปพพ. ม.386)
B5: สัญญา | C5: ลูกค้า | D5: สถานะ | E5: ค้าง (งวด) | F5: ค้างเก่าสุด (วัน) | G5: Action
B6: FIN-2024-003 | C6: สมศักดิ์ | D6: ACTIVE | E6: 1 | F6: 15 | G6: =IF(AND(F6>=90,D6="TERMINATED"),"📦 พร้อม JP5",IF(F6>=60,"⚠ ออกหนังสือบอกเลิก",IF(F6>=45,"✉ หนังสือเตือน 45 วัน",IF(F6>0,"⏳ ติดตามปกติ","✔ ปกติ")))) -> ⏳ ติดตามปกติ
B7: FIN-2024-012 | C7: วิภาดา | D7: ACTIVE | E7: 1 | F7: 15 | G7: =IF(AND(F7>=90,D7="TERMINATED"),"📦 พร้อม JP5",IF(F7>=60,"⚠ ออกหนังสือบอกเลิก",IF(F7>=45,"✉ หนังสือเตือน 45 วัน",IF(F7>0,"⏳ ติดตามปกติ","✔ ปกติ")))) -> ⏳ ติดตามปกติ
B8: FIN-2024-004 | C8: ประเสริฐ | D8: OVERDUE | E8: 3 | F8: 75 | G8: =IF(AND(F8>=90,D8="TERMINATED"),"📦 พร้อม JP5",IF(F8>=60,"⚠ ออกหนังสือบอกเลิก",IF(F8>=45,"✉ หนังสือเตือน 45 วัน",IF(F8>0,"⏳ ติดตามปกติ","✔ ปกติ")))) -> ⚠ ออกหนังสือบอกเลิก
B9: FIN-2024-010 | C9: จันทร์เพ็ญ | D9: TERMINATED | E9: 5 | F9: 135 | G9: =IF(AND(F9>=90,D9="TERMINATED"),"📦 พร้อม JP5",IF(F9>=60,"⚠ ออกหนังสือบอกเลิก",IF(F9>=45,"✉ หนังสือเตือน 45 วัน",IF(F9>0,"⏳ ติดตามปกติ","✔ ปกติ")))) -> 📦 พร้อม JP5 | H9: ← แก้จาก v3: เดิมใส่ "รอติดตาม" ขัดกับ summary ตัวเอง (ค้าง 135 วัน ≥ 90 เหมือน FIN-2024-067)
B10: FIN-2024-067 | C10: อนุชา | D10: TERMINATED | E10: 5 | F10: 135 | G10: =IF(AND(F10>=90,D10="TERMINATED"),"📦 พร้อม JP5",IF(F10>=60,"⚠ ออกหนังสือบอกเลิก",IF(F10>=45,"✉ หนังสือเตือน 45 วัน",IF(F10>0,"⏳ ติดตามปกติ","✔ ปกติ")))) -> 📦 พร้อม JP5
B11: FIN-2024-089 | C11: รัตนา | D11: TERMINATED | E11: 6 | F11: 165 | G11: =IF(AND(F11>=90,D11="TERMINATED"),"📦 พร้อม JP5",IF(F11>=60,"⚠ ออกหนังสือบอกเลิก",IF(F11>=45,"✉ หนังสือเตือน 45 วัน",IF(F11>0,"⏳ ติดตามปกติ","✔ ปกติ")))) -> 📦 พร้อม JP5
B12: FIN-2024-005 | C12: สมหมาย | D12: TERMINATED | E12: 7 | F12: 195 | G12: =IF(AND(F12>=90,D12="TERMINATED"),"📦 พร้อม JP5",IF(F12>=60,"⚠ ออกหนังสือบอกเลิก",IF(F12>=45,"✉ หนังสือเตือน 45 วัน",IF(F12>0,"⏳ ติดตามปกติ","✔ ปกติ")))) -> 📦 พร้อม JP5
B13: FIN-2024-045 | C13: กิตติพงษ์ | D13: TERMINATED | E13: 7 | F13: 195 | G13: =IF(AND(F13>=90,D13="TERMINATED"),"📦 พร้อม JP5",IF(F13>=60,"⚠ ออกหนังสือบอกเลิก",IF(F13>=45,"✉ หนังสือเตือน 45 วัน",IF(F13>0,"⏳ ติดตามปกติ","✔ ปกติ")))) -> 📦 พร้อม JP5
B14: FIN-2024-023 | C14: ดวงใจ | D14: TERMINATED | E14: 7 | F14: 195 | G14: =IF(AND(F14>=90,D14="TERMINATED"),"📦 พร้อม JP5",IF(F14>=60,"⚠ ออกหนังสือบอกเลิก",IF(F14>=45,"✉ หนังสือเตือน 45 วัน",IF(F14>0,"⏳ ติดตามปกติ","✔ ปกติ")))) -> 📦 พร้อม JP5
B15: FIN-2024-101 | C15: ศิริพร | D15: ACTIVE (B0) | E15: 0 | F15: 0 | G15: =IF(AND(F15>=90,D15="TERMINATED"),"📦 พร้อม JP5",IF(F15>=60,"⚠ ออกหนังสือบอกเลิก",IF(F15>=45,"✉ หนังสือเตือน 45 วัน",IF(F15>0,"⏳ ติดตามปกติ","✔ ปกติ")))) -> ✔ ปกติ
B17: สรุป: พร้อม JP5 = | E17: =COUNTIF(G6:G15,"📦 พร้อม JP5") -> 6 | F17: (v3 นับ 6 แต่แถว FIN-2024-010 เขียนขัด — v4 แถวกับ summary ตรงกันแล้ว)

Sheet 8-CPA-Note
B2: หมายเหตุถึง CPA + ขอคำยืนยัน
B4: ข้อสังเกต/นโยบายที่ระบบใช้ (แจ้งเพื่อทราบ)
B5: ก | C5: แยกงวด: provision = Σ ต่องวด ROUND(ยอดค้างสุทธิ × rate ตามอายุงวดนั้น, 2) — ปัดต่องวดก่อนรวม (ROUND_HALF_UP) | D5: ตัวอย่าง: ค้าง 90/60/30 วัน = 757.92+227.37+30.32 = 1,015.61
B6: ข | C6: TERMINATED ตั้งค่าเผื่อเฉพาะงวดที่ accrue เข้า 11-2103 แล้ว (งวดหลังบอกเลิกไม่ตั้ง — ดอกเบี้ย/VAT ยังไม่รับรู้) | D6: ตัวอย่างระบบ: 3 งวด accrued + 2 งวดเลยกำหนดแต่ไม่ accrue → 2,122.16 (ไม่ใช่ 2,183.12)
B7: ค | C7: ฐานยอดค้างหักค่าปรับก่อน (FEE-FIRST): เงินรับตัดค่าปรับก่อนแล้วค่อยตัดงวด — ฐาน ECL/CN = ยอดค้างสุทธิจริง | D7: จ่าย 1,000 (มีค่าปรับ 75.79) → ตัดต้น 924.21 → ค้าง 591.62 → CN VAT 38.71
B8: ง | C8: นโยบายสตางค์: ระบบ GL-based เป็น canonical — ต่างจากคูณจำนวนงวด ±0.04-0.08 (เศษปัด 99.17×12 = 1,190.04) ถูกกวาดปิดใน JP5 | D8: เช่น Net VAT Scenario D: count-based 793.36 / GL-based 793.32
B9: จ | C9: JP5/write-off: consume ค่าเผื่อ = min(Loss, GL 11-2102) แล้ว release ส่วนเหลือ (Dr 11-2102 / Cr 51-1103) ใน JE เดียวกัน → 11-2102 ของสัญญาเป็น 0 เสมอ | D9: Sheet 6 คอลัมน์ Release
B11: ขอคำยืนยัน 2 ข้อ (ก่อนระบบขึ้น production)
B12: 1 | C12: ยืนยันวิธีคิดค่าเผื่อแบบ "แยกงวด" (per-installment aging) ตาม Sheet 2-3 แทนวิธีทั้งสัญญา × rate งวดเก่าสุด | D12: ยืนยัน: ☐ ใช่ ☐ ปรับ (ระบุ): ____________
B13: 2 | C13: ยืนยันปิดกติกา "ค้างติดต่อกัน N งวด → floor bucket" (consecutive-missed) — workbook นี้ไม่ใช้ floor; ถ้าต้องการเปิดกลับ โปรดระบุตาราง N → bucket | D13: ยืนยัน: ☐ ใช่ ☐ ปรับ (ระบุ): ____________
C15: อ้างอิงระบบ: branch feat/ecl-per-installment | goldens: bad-debt.service.spec.ts / jp5-vat-split.spec.ts / ecl-terminated-base.spec.ts / compute-cn-breakdown.spec.ts
